<?xml version="1.0"?>
<robot
  name="snake_arm_description">

  <link name="world" />

  <joint name="world_to_base_link" type="fixed">
    <parent link="world"/>
    <child link="link_0"/>
  </joint>

  <link
    name="link_0">
    <inertial>
      <origin
        xyz="-4.4729E-05 0.0001093 0.075199"
        rpy="0 0 0" />
      <mass
        value="0.48102" />
      <inertia
        ixx="0.0016739"
        ixy="1.507E-06"
        ixz="1.7594E-06"
        iyy="0.0017323"
        iyz="-4.257E-05"
        izz="0.0005214" />
    </inertial>
    <visual>
      <origin
        xyz="0 0 0"
        rpy="0 0 0" />
      <geometry>
        <mesh
          filename="package://snake_arm_description/meshes/link_0.STL" />
      </geometry>
      <material
        name="">
        <color
          rgba="0.79216 0.81961 0.93333 1" />
      </material>
    </visual>
    <collision>
      <origin
        xyz="0 0 0"
        rpy="0 0 0" />
      <geometry>
        <mesh
          filename="package://snake_arm_description/meshes/link_0.STL" />
      </geometry>
    </collision>
  </link>
  <link
    name="link_1">
    <inertial>
      <origin
        xyz="0.00871 -0.0013532 0.1245"
        rpy="0 0 0" />
      <mass
        value="0.37472" />
      <inertia
        ixx="0.0011935"
        ixy="-8.7083E-07"
        ixz="-4.8583E-05"
        iyy="0.0012712"
        iyz="3.2382E-05"
        izz="0.00034763" />
    </inertial>
    <visual>
      <origin
        xyz="0 0 0"
        rpy="0 0 0" />
      <geometry>
        <mesh
          filename="package://snake_arm_description/meshes/link_1.STL" />
      </geometry>
      <material
        name="">
        <color
          rgba="0.79216 0.81961 0.93333 1" />
      </material>
    </visual>
    <collision>
      <origin
        xyz="0 0 0"
        rpy="0 0 0" />
      <geometry>
        <mesh
          filename="package://snake_arm_description/meshes/link_1.STL" />
      </geometry>
    </collision>
  </link>
  <joint
    name="joint_0"
    type="revolute">
    <origin
      xyz="0 -0.01 0.135"
      rpy="0 0 1.5708" />
    <parent
      link="link_0" />
    <child
      link="link_1" />
    <axis
      xyz="1 0 0" />
    <limit
      lower="-1.5708"
      upper="1.5708"
      effort="0"
      velocity="0.1745" />
  </joint>
  <link
    name="link_2">
    <inertial>
      <origin
        xyz="0.00871 -0.0013532 0.1245"
        rpy="0 0 0" />
      <mass
        value="0.37472" />
      <inertia
        ixx="0.0011935"
        ixy="-8.7083E-07"
        ixz="-4.8583E-05"
        iyy="0.0012712"
        iyz="3.2382E-05"
        izz="0.00034763" />
    </inertial>
    <visual>
      <origin
        xyz="0 0 0"
        rpy="0 0 0" />
      <geometry>
        <mesh
          filename="package://snake_arm_description/meshes/link_2.STL" />
      </geometry>
      <material
        name="">
        <color
          rgba="0.79216 0.81961 0.93333 1" />
      </material>
    </visual>
    <collision>
      <origin
        xyz="0 0 0"
        rpy="0 0 0" />
      <geometry>
        <mesh
          filename="package://snake_arm_description/meshes/link_2.STL" />
      </geometry>
    </collision>
  </link>
  <joint
    name="joint_1"
    type="revolute">
    <origin
      xyz="0.01 0.01 0.17"
      rpy="0 0 -1.5708" />
    <parent
      link="link_1" />
    <child
      link="link_2" />
    <axis
      xyz="1 0 0" />
    <limit
      lower="-1.5708"
      upper="1.5708"
      effort="0"
      velocity="0.1745" />
  </joint>
  <link
    name="link_3">
    <inertial>
      <origin
        xyz="-0.0092113 -0.0012358 0.11639"
        rpy="0 0 0" />
      <mass
        value="0.30664" />
      <inertia
        ixx="0.00087659"
        ixy="-1.1893E-06"
        ixz="3.6915E-05"
        iyy="0.00086986"
        iyz="-2.665E-05"
        izz="0.00026908" />
    </inertial>
    <visual>
      <origin
        xyz="0 0 0"
        rpy="0 0 0" />
      <geometry>
        <mesh
          filename="package://snake_arm_description/meshes/link_3.STL" />
      </geometry>
      <material
        name="">
        <color
          rgba="0.79216 0.81961 0.93333 1" />
      </material>
    </visual>
    <collision>
      <origin
        xyz="0 0 0"
        rpy="0 0 0" />
      <geometry>
        <mesh
          filename="package://snake_arm_description/meshes/link_3.STL" />
      </geometry>
    </collision>
  </link>
  <joint
    name="joint_2"
    type="revolute">
    <origin
      xyz="0.01 0.01 0.17"
      rpy="1.6355E-32 1.8825E-16 1.5708" />
    <parent
      link="link_2" />
    <child
      link="link_3" />
    <axis
      xyz="-1 0 0" />
    <limit
      lower="-1.5708"
      upper="1.5708"
      effort="0"
      velocity="0.1745" />
  </joint>
  <link
    name="link_4">
    <inertial>
      <origin
        xyz="-0.0071513 -0.001245 0.11452"
        rpy="0 0 0" />
      <mass
        value="0.30403" />
      <inertia
        ixx="0.00082745"
        ixy="-1.2195E-06"
        ixz="3.7353E-05"
        iyy="0.00082575"
        iyz="-2.7039E-05"
        izz="0.00026963" />
    </inertial>
    <visual>
      <origin
        xyz="0 0 0"
        rpy="0 0 0" />
      <geometry>
        <mesh
          filename="package://snake_arm_description/meshes/link_4.STL" />
      </geometry>
      <material
        name="">
        <color
          rgba="0.79216 0.81961 0.93333 1" />
      </material>
    </visual>
    <collision>
      <origin
        xyz="0 0 0"
        rpy="0 0 0" />
      <geometry>
        <mesh
          filename="package://snake_arm_description/meshes/link_4.STL" />
      </geometry>
    </collision>
  </link>
  <joint
    name="joint_3"
    type="revolute">
    <origin
      xyz="-0.01 -0.008 0.164"
      rpy="1.8825E-16 0 -1.5708" />
    <parent
      link="link_3" />
    <child
      link="link_4" />
    <axis
      xyz="-1 0 0" />
    <limit
      lower="-1.5708"
      upper="1.5708"
      effort="0"
      velocity="0.1745" />
  </joint>
  <link
    name="link_5">
    <inertial>
      <origin
        xyz="0.0071513 0.001245 0.11452"
        rpy="0 0 0" />
      <mass
        value="0.30403" />
      <inertia
        ixx="0.00082745"
        ixy="-1.2195E-06"
        ixz="-3.7353E-05"
        iyy="0.00082575"
        iyz="2.7039E-05"
        izz="0.00026963" />
    </inertial>
    <visual>
      <origin
        xyz="0 0 0"
        rpy="0 0 0" />
      <geometry>
        <mesh
          filename="package://snake_arm_description/meshes/link_5.STL" />
      </geometry>
      <material
        name="">
        <color
          rgba="0.79216 0.81961 0.93333 1" />
      </material>
    </visual>
    <collision>
      <origin
        xyz="0 0 0"
        rpy="0 0 0" />
      <geometry>
        <mesh
          filename="package://snake_arm_description/meshes/link_5.STL" />
      </geometry>
    </collision>
  </link>
  <joint
    name="joint_4"
    type="revolute">
    <origin
      xyz="-0.008 -0.008 0.161"
      rpy="6.3966E-64 4.9304E-32 1.5708" />
    <parent
      link="link_4" />
    <child
      link="link_5" />
    <axis
      xyz="1 0 0" />
    <limit
      lower="-1.5708"
      upper="1.5708"
      effort="0"
      velocity="0.1745" />
  </joint>
  <link
    name="link_6">
    <inertial>
      <origin
        xyz="0.0048917 0.0022417 0.10273"
        rpy="0 0 0" />
      <mass
        value="0.10778" />
      <inertia
        ixx="0.00023402"
        ixy="-8.5749E-07"
        ixz="-3.2807E-05"
        iyy="0.00024219"
        iyz="-6.4841E-06"
        izz="6.9634E-05" />
    </inertial>
    <visual>
      <origin
        xyz="0 0 0"
        rpy="0 0 0" />
      <geometry>
        <mesh
          filename="package://snake_arm_description/meshes/link_6.STL" />
      </geometry>
      <material
        name="">
        <color
          rgba="0.79216 0.81961 0.93333 1" />
      </material>
    </visual>
    <collision>
      <origin
        xyz="0 0 0"
        rpy="0 0 0" />
      <geometry>
        <mesh
          filename="package://snake_arm_description/meshes/link_6.STL" />
      </geometry>
    </collision>
  </link>
  <joint
    name="joint_5"
    type="revolute">
    <origin
      xyz="0.008 0.008 0.161"
      rpy="4.9304E-32 0 -1.5708" />
    <parent
      link="link_5" />
    <child
      link="link_6" />
    <axis
      xyz="1 0 0" />
    <limit
      lower="-1.5708"
      upper="1.5708"
      effort="0"
      velocity="0.1745" />
  </joint>
  <link
    name="link_7">
    <inertial>
      <origin
        xyz="-0.00073318 -1.1397E-06 0.070942"
        rpy="0 0 0" />
      <mass
        value="0.06189" />
      <inertia
        ixx="0.00010919"
        ixy="-6.4144E-10"
        ixz="-2.8296E-06"
        iyy="0.00011192"
        iyz="-4.7723E-09"
        izz="6.0877E-05" />
    </inertial>
    <visual>
      <origin
        xyz="0 0 0"
        rpy="0 0 0" />
      <geometry>
        <mesh
          filename="package://snake_arm_description/meshes/link_7.STL" />
      </geometry>
      <material
        name="">
        <color
          rgba="0.79216 0.81961 0.93333 1" />
      </material>
    </visual>
    <collision>
      <origin
        xyz="0 0 0"
        rpy="0 0 0" />
      <geometry>
        <mesh
          filename="package://snake_arm_description/meshes/link_7.STL" />
      </geometry>
    </collision>
  </link>
  <joint
    name="joint_6"
    type="revolute">
    <origin
      xyz="0.008 0 0.13613"
      rpy="2.1894E-32 1.6653E-16 1.5708" />
    <parent
      link="link_6" />
    <child
      link="link_7" />
    <axis
      xyz="1 0 0" />
    <limit
      lower="-1.5708"
      upper="1.5708"
      effort="0"
      velocity="0.1745" />
  </joint>
</robot>